Workbook

Sheet Summary
A1: RESTORING HOPE
A2: PROJECT BUDGET TEMPLATE
A4: Project Title | C4: Hands That Heal: Certifying Gaza's Next Generation of Prosthetists
A5: Program Summary | C5: Capacity building of 16 P&O technicians + integrated prosthetic fitting and holistic care (rehabilitation, MHPSS, nutrition, transport) for 300 amputees in Gaza
A6: Project Duration | C6: 18 Months
A7: Locations | C7: Gaza (field implementation) & Amman (technical and administrative support)
A8: Project Code | C8: RHS202600XXX
A9: Organization | C9: Restoring Hope (RHS)
A10: Currency | C10: USD
A12: BUDGET SUMMARY BY CATEGORY
A13: # | B13: Budget Category | C13: Amount (USD) | D13: % of Total
A14: 1 | B14: Direct Cost (Gaza field personnel, specialists, training, patient care, equipment, visibility) | C14: ='Direct Cost'!K48 -> 2348106.2 | D14: =C14/C$16 -> 0.86956522
A15: 2 | B15: Admin / Indirect Cost (Amman support functions) | C15: ='Admin Cost'!K40 -> 352215.93 | D15: =C15/C$16 -> 0.13043478
B16: TOTAL PROJECT BUDGET | C16: =SUM(C14:C15) -> 2700322.1 | D16: 1
A18: BUDGET SUMMARY BY ACCOUNT
A19: Account No. | B19: Account Name | C19: Amount (USD) | D19: % of Total
A20: ='Accounts & Activity'!B2 -> 2601 | B20: ='Accounts & Activity'!A2 -> Program Field Staff | C20: =SUMIF('Direct Cost'!$C:$C,$A20,'Direct Cost'!$K:$K)+SUMIF('Admin Cost'!$C:$C,$A20,'Admin Cost'!$K:$K) -> 48600 | D20: =C20/$C$48 -> 0.028582819
A21: ='Accounts & Activity'!B3 -> 2602 | B21: ='Accounts & Activity'!A3 -> Management Field Staff | C21: =SUMIF('Direct Cost'!$C:$C,$A21,'Direct Cost'!$K:$K)+SUMIF('Admin Cost'!$C:$C,$A21,'Admin Cost'!$K:$K) -> 0 | D21: =C21/$C$48 -> 0
A22: ='Accounts & Activity'!B4 -> 2603 | B22: ='Accounts & Activity'!A4 -> Head Office staff | C22: =SUMIF('Direct Cost'!$C:$C,$A22,'Direct Cost'!$K:$K)+SUMIF('Admin Cost'!$C:$C,$A22,'Admin Cost'!$K:$K) -> 0 | D22: =C22/$C$48 -> 0
A23: ='Accounts & Activity'!B5 -> 2604 | B23: ='Accounts & Activity'!A5 -> Support Field staff | C23: =SUMIF('Direct Cost'!$C:$C,$A23,'Direct Cost'!$K:$K)+SUMIF('Admin Cost'!$C:$C,$A23,'Admin Cost'!$K:$K) -> 0 | D23: =C23/$C$48 -> 0
A24: ='Accounts & Activity'!B6 -> 2605 | B24: ='Accounts & Activity'!A6 -> Staff Transportation | C24: =SUMIF('Direct Cost'!$C:$C,$A24,'Direct Cost'!$K:$K)+SUMIF('Admin Cost'!$C:$C,$A24,'Admin Cost'!$K:$K) -> 0 | D24: =C24/$C$48 -> 0
A25: ='Accounts & Activity'!B7 -> 2606 | B25: ='Accounts & Activity'!A7 -> Ben Transportation | C25: =SUMIF('Direct Cost'!$C:$C,$A25,'Direct Cost'!$K:$K)+SUMIF('Admin Cost'!$C:$C,$A25,'Admin Cost'!$K:$K) -> 45000 | D25: =C25/$C$48 -> 0.026465573
A26: ='Accounts & Activity'!B8 -> 2607 | B26: ='Accounts & Activity'!A8 -> Car Rent | C26: =SUMIF('Direct Cost'!$C:$C,$A26,'Direct Cost'!$K:$K)+SUMIF('Admin Cost'!$C:$C,$A26,'Admin Cost'!$K:$K) -> 0 | D26: =C26/$C$48 -> 0
A27: ='Accounts & Activity'!B9 -> 2608 | B27: ='Accounts & Activity'!A9 -> Fuel for generator or Car | C27: =SUMIF('Direct Cost'!$C:$C,$A27,'Direct Cost'!$K:$K)+SUMIF('Admin Cost'!$C:$C,$A27,'Admin Cost'!$K:$K) -> 0 | D27: =C27/$C$48 -> 0
A28: ='Accounts & Activity'!B10 -> 2609 | B28: ='Accounts & Activity'!A10 -> IT Equipment | C28: =SUMIF('Direct Cost'!$C:$C,$A28,'Direct Cost'!$K:$K)+SUMIF('Admin Cost'!$C:$C,$A28,'Admin Cost'!$K:$K) -> 12000 | D28: =C28/$C$48 -> 0.0070574862
A29: ='Accounts & Activity'!B11 -> 2610 | B29: ='Accounts & Activity'!A11 -> Project / Center Equipments | C29: =SUMIF('Direct Cost'!$C:$C,$A29,'Direct Cost'!$K:$K)+SUMIF('Admin Cost'!$C:$C,$A29,'Admin Cost'!$K:$K) -> 223000 | D29: =C29/$C$48 -> 0.13115162
A30: ='Accounts & Activity'!B12 -> 2611 | B30: ='Accounts & Activity'!A12 -> Prosthetics components | C30: =SUMIF('Direct Cost'!$C:$C,$A30,'Direct Cost'!$K:$K)+SUMIF('Admin Cost'!$C:$C,$A30,'Admin Cost'!$K:$K) -> 500000 | D30: =C30/$C$48 -> 0.29406193
A31: ='Accounts & Activity'!B13 -> 2612 | B31: ='Accounts & Activity'!A13 -> Media Equipments | C31: =SUMIF('Direct Cost'!$C:$C,$A31,'Direct Cost'!$K:$K)+SUMIF('Admin Cost'!$C:$C,$A31,'Admin Cost'!$K:$K) -> 30000 | D31: =C31/$C$48 -> 0.017643716
... A47: ='Accounts & Activity'!B29 -> 2628 | B47: ='Accounts & Activity'!A29 -> Contingency | C47: =SUMIF('Direct Cost'!$C:$C,$A47,'Direct Cost'!$K:$K)+SUMIF('Admin Cost'!$C:$C,$A47,'Admin Cost'!$K:$K) -> 195895.93 | D47: =C47/$C$48 -> 0.11521107
A48: TOTAL | C48: =SUM(C20:C47) -> 1700322.1 | D48: =SUM(D20:D47) -> 1
A50: BUDGET SUMMARY BY ACTIVITY
A51: Code | B51: Activity | C51: Amount (USD) | D51: % of Total
A52: S | B52: Support | C52: =SUMIF('Direct Cost'!$B:$B,"S*",'Direct Cost'!$K:$K)+SUMIF('Admin Cost'!$B:$B,"S*",'Admin Cost'!$K:$K) -> 382215.93 | D52: =C52/$C$58 -> 0.2247903
A53: R | B53: Rehabilitation | C53: =SUMIF('Direct Cost'!$B:$B,"R*",'Direct Cost'!$K:$K)+SUMIF('Admin Cost'!$B:$B,"R*",'Admin Cost'!$K:$K) -> 41200 | D53: =C53/$C$58 -> 0.024230703
A54: M | B54: MHPSS | C54: =SUMIF('Direct Cost'!$B:$B,"M*",'Direct Cost'!$K:$K)+SUMIF('Admin Cost'!$B:$B,"M*",'Admin Cost'!$K:$K) -> 16200 | D54: =C54/$C$58 -> 0.0095276064
A55: N | B55: Nutrition | C55: =SUMIF('Direct Cost'!$B:$B,"N*",'Direct Cost'!$K:$K)+SUMIF('Admin Cost'!$B:$B,"N*",'Admin Cost'!$K:$K) -> 162000 | D55: =C55/$C$58 -> 0.095276064
A56: P | B56: P&O | C56: =SUMIF('Direct Cost'!$B:$B,"P0*",'Direct Cost'!$K:$K)+SUMIF('Admin Cost'!$B:$B,"P0*",'Admin Cost'!$K:$K) -> 1098706.2 | D56: =C56/$C$58 -> 0.64617532
A57: PM | B57: Program Support / Management | C57: =SUMIF('Direct Cost'!$B:$B,"PM*",'Direct Cost'!$K:$K)+SUMIF('Admin Cost'!$B:$B,"PM*",'Admin Cost'!$K:$K) -> 0 | D57: =C57/$C$58 -> 0
A58: TOTAL | C58: =SUM(C52:C57) -> 1700322.1 | D58: =SUM(D52:D57) -> 1

Sheet Direct Cost
A1: RESTORING HOPE - Project Budget: Direct Costs
A2: Hands That Heal: Certifying Gaza's Next Generation of Prosthetists , Capacity Building & 300-Case Integrated Prosthetic Care Program
A3: Project Duration: | D3: 18 Months
A4: Location: | D4: Gaza (field) & Amman (support) | H4: Currency: | I4: USD
A5: Code | B5: Activity Code | C5: Account No. | D5: Location | E5: Position / Line Item | F5: Unit | G5: # of Units | H5: Frequency (Months) | I5: Unit Cost (USD) | J5: LoE % | K5: Total (USD)
A6: A. Personnel — Gaza Field Team (100% Direct Cost)
A7: D-01 | B7: S02 | C7: 2602 | D7: Gaza | E7: Project Manager | F7: Person | G7: 1 | H7: 18 | I7: 0 | J7: 1 | K7: =G7*H7*I7*J7 -> 0
A8: D-02 | B8: R02 | C8: 2602 | D8: Gaza | E8: Program Officer — Rehabilitation | F8: Person | G8: 1 | H8: 18 | I8: 0 | J8: 1 | K8: =G8*H8*I8*J8 -> 0
A9: D-03 | B9: M02 | C9: 2602 | D9: Gaza | E9: Program Officer — MHPSS | F9: Person | G9: 1 | H9: 18 | I9: 0 | J9: 1 | K9: =G9*H9*I9*J9 -> 0
A10: D-04 | B10: R02 | C10: 2601 | D10: Gaza | E10: Mobile Team Member — Rehabilitation (x6) | F10: Person | G10: 6 | H10: 18 | I10: 0 | J10: 1 | K10: =G10*H10*I10*J10 -> 0
A11: D-05 | B11: M02 | C11: 2601 | D11: Gaza | E11: Mobile Team Member — MHPSS (x6) | F11: Person | G11: 6 | H11: 18 | I11: 0 | J11: 1 | K11: =G11*H11*I11*J11 -> 0
A12: D-06 | B12: PM02 | C12: 2601 | D12: Gaza | E12: MEAL Officer | F12: Person | G12: 1 | H12: 18 | I12: 0 | J12: 1 | K12: =G12*H12*I12*J12 -> 0
A13: D-07 | B13: PM02 | C13: 2604 | D13: Gaza | E13: Photographer / Visibility Officer | F13: Person | G13: 1 | H13: 18 | I13: 0 | J13: 1 | K13: =G13*H13*I13*J13 -> 0
A14: D-08 | B14: S02 | C14: 2604 | D14: Gaza | E14: Security Guard (x2) | F14: Person | G14: 2 | H14: 18 | I14: 0 | J14: 1 | K14: =G14*H14*I14*J14 -> 0
A15: D-09 | B15: S02 | C15: 2604 | D15: Gaza | E15: Cleaner (x2) | F15: Person | G15: 2 | H15: 18 | I15: 0 | J15: 1 | K15: =G15*H15*I15*J15 -> 0
A16: D-25 | B16: S02 | C16: 2604 | D16: Gaza | E16: Logistic Officer | F16: Person | G16: 1 | H16: 18 | I16: 0 | J16: 1 | K16: =G16*H16*I16*J16 -> 0
A17: Subtotal — Personnel — Gaza Field Team (100% Direct Cost) | K17: 1000000
A19: B. Specialist & Technical Personnel (Direct Cost)
A20: D-10 | B20: P02 | C20: 2613 | D20: Amman | E20: P&O Specialist Consultant (Academic & Clinical Oversight) | F20: Lump | G20: 1 | H20: 1 | I20: 15087 | J20: 1 | K20: =G20*H20*I20*J20 -> 15087
A21: D-13 | B21: P02 | C21: 2615 | D21: Gaza & Amman | E21: Gaza University & University of Jordan Course Fees | F21: Person | G21: 16 | H21: 1 | I21: 3976.2 | J21: 1 | K21: =G21*H21*I21*J21 -> 63619.2
A22: D-22 | B22: P01 | C22: 2601 | D22: Amman | E22: P&O Specialist (Amman-based, supporting Gaza) | F22: Person | G22: 1 | H22: 18 | I22: 3000 | J22: 0.3 | K22: =G22*H22*I22*J22 -> 16200
A23: D-23 | B23: R01 | C23: 2601 | D23: Amman | E23: Rehabilitation Specialist (Amman-based, supporting Gaza) | F23: Person | G23: 1 | H23: 18 | I23: 3000 | J23: 0.3 | K23: =G23*H23*I23*J23 -> 16200
A24: D-24 | B24: M01 | C24: 2601 | D24: Amman | E24: MHPSS Specialist (Amman-based, supporting Gaza) | F24: Person | G24: 1 | H24: 18 | I24: 3000 | J24: 0.3 | K24: =G24*H24*I24*J24 -> 16200
A25: Subtotal — Specialist & Technical Personnel (Direct Cost) | K25: =SUM(K20:K24) -> 127306.2
A27: C. Capacity Building & Training Costs (Direct Cost)
A28: D-14a | B28: P02 | C28: 2615 | D28: Gaza | E28: Trainee Incentives — Cohort 1 (8 trainees, 17 months) | F28: Person | G28: 8 | H28: 17 | I28: 400 | J28: 1 | K28: =G28*H28*I28*J28 -> 54400
A29: D-14b | B29: P02 | C29: 2615 | D29: Gaza | E29: Trainee Incentives — Cohort 2 (8 trainees, 12 months) | F29: Person | G29: 8 | H29: 12 | I29: 400 | J29: 1 | K29: =G29*H29*I29*J29 -> 38400
A30: D-15 | B30: P02 | C30: 2613 | D30: Gaza | E30: Certified Expatriate Specialist Trainer and P&O (6 Specialist Trainers) | F30: Person | G30: 8 | H30: 3 | I30: 7000 | J30: 1 | K30: =G30*H30*I30*J30 -> 168000
A31: Subtotal — Capacity Building & Training Costs (Direct Cost) | K31: =SUM(K28:K30) -> 260800
A33: D. Prosthetic Fitting & Integrated Patient Care — 300 Cases (Direct Cost)
A34: D-16 | B34: P02 | C34: 2611 | D34: Gaza | E34: Prosthetic Components & Fabrication Materials (300 cases) | F34: Lum | G34: 1 | H34: 1 | I34: 500000 | J34: 1 | K34: 500000
A35: D-17 | B35: N02 | C35: 2626 | D35: Gaza | E35: Nutritional Support (300 HH) | F35: Person | G35: 300 | H35: 3 | I35: 180 | J35: 1 | K35: =G35*H35*I35*J35 -> 162000
A36: D-18 | B36: P02 | C36: 2606 | D36: Gaza | E36: Patient Transport & Accompaniment (300 patients) | F36: Month | G36: 12 | H36: 1 | I36: 3750 | J36: 1 | K36: =G36*H36*I36*J36 -> 45000
A37: Subtotal — Prosthetic Fitting & Integrated Patient Care — 300 Cases (Direct Cost) | K37: =SUM(K34:K36) -> 707000
A39: E. Workshop Equipment & Infrastructure (Direct Cost)
A40: D-19 | B40: P02 | C40: 2610 | D40: Gaza | E40: P&O Workshop Machinery & Fabrication Equipment | F40: Lum | G40: 1 | H40: 1 | I40: 198000 | J40: 1 | K40: =G40*H40*I40*J40 -> 198000
A41: D-20 | B41: R02 | C41: 2610 | D41: Gaza | E41: Rehabilitation & MHPSS Zone Furnishing (Zone 10) | F41: Lump | G41: 1 | H41: 1 | I41: 25000 | J41: 1 | K41: =G41*H41*I41*J41 -> 25000
A42: Subtotal — Workshop Equipment & Infrastructure (Direct Cost) | K42: =SUM(K40:K41) -> 223000
A44: F. Visibility & Communications (Direct Cost)
A45: D-21 | B45: S02 | C45: 2612 | D45: Gaza & Amman | E45: Communication & Visibility Materials | F45: Lump | G45: 1 | H45: 1 | I45: 30000 | J45: 1 | K45: =G45*H45*I45*J45 -> 30000
...

Sheet Admin Cost
A1: RESTORING HOPE — Project Budget: Admin / Indirect Costs
A2: Organizational support functions allocated to the Gaza 300-Case Integrated Prosthetic Care & Capacity Building Program
A3: Project Duration: | D3: 18 Months | H3: Prepared by: | I3: Bilal Abbassi, Programs Director
A4: Location: | D4: Gaza (field) & Amman (support) | H4: Currency: | I4: USD
A5: Code | B5: Activity Code | C5: Account No. | D5: Location | E5: Position / Line Item | F5: Unit | G5: # of Units | H5: Frequency (Months) | I5: Unit Cost (USD) | J5: % Allocated | K5: Total (USD)
A6: A. Amman Support Personnel (Indirect / Admin — salaries converted JOD → USD, % LoE charged)
A7: A-01 | B7: PM01 | C7: 2603 | D7: Amman | E7: Executive Director | F7: Person | G7: 1 | H7: 18 | I7: 0 | J7: 0.12 | K7: =G7*H7*I7*J7 -> 0
A8: A-02 | B8: S01 | C8: 2603 | D8: Amman | E8: Program Director | F8: Person | G8: 1 | H8: 18 | I8: 0 | J8: 0.18 | K8: =G8*H8*I8*J8 -> 0
A9: A-03 | B9: PM01 | C9: 2603 | D9: Amman | E9: Grants & Compliance Officer | F9: Person | G9: 1 | H9: 18 | I9: 0 | J9: 0.22 | K9: =G9*H9*I9*J9 -> 0
A10: A-04 | B10: S01 | C10: 2603 | D10: Amman | E10: Finance & Support Function Director | F10: Person | G10: 1 | H10: 18 | I10: 0 | J10: 0.2 | K10: =G10*H10*I10*J10 -> 0
A11: A-05 | B11: S01 | C11: 2603 | D11: Amman | E11: Supply Chain / Logistics Officer | F11: Person | G11: 1 | H11: 18 | I11: 0 | J11: 0.28 | K11: =G11*H11*I11*J11 -> 0
A12: A-06 | B12: S01 | C12: 2603 | D12: Amman | E12: HR & Admin Officer | F12: Person | G12: 1 | H12: 18 | I12: 0 | J12: 0.22 | K12: =G12*H12*I12*J12 -> 0
A13: A-07 | B13: PM01 | C13: 2603 | D13: Amman | E13: Communications Team Leader | F13: Person | G13: 1 | H13: 18 | I13: 0 | J13: 0.18 | K13: =G13*H13*I13*J13 -> 0
A14: A-08 | B14: PM01 | C14: 2603 | D14: Amman | E14: M&E / Reporting Officer (HQ oversight) | F14: Person | G14: 1 | H14: 18 | I14: 0 | J14: 0.18 | K14: =G14*H14*I14*J14 -> 0
A15: A-09 | B15: S01 | C15: 2603 | D15: Amman | E15: IT / Database Support Officer | F15: Person | G15: 1 | H15: 18 | I15: 0 | J15: 0.18 | K15: =G15*H15*I15*J15 -> 0
A16: A-10 | B16: PM01 | C16: 2603 | D16: Amman | E16: Content Creator | F16: Person | G16: 1 | H16: 18 | I16: 0 | J16: 0.35 | K16: =G16*H16*I16*J16 -> 0
A17: A-11 | B17: PM01 | C17: 2603 | D17: Amman | E17: Video Editor | F17: Person | G17: 1 | H17: 18 | I17: 0 | J17: 0.28 | K17: =G17*H17*I17*J17 -> 0
A18: A-12 | B18: S01 | C18: 2603 | D18: Amman | E18: Driver | F18: Person | G18: 1 | H18: 18 | I18: 0 | J18: 0.35 | K18: =G18*H18*I18*J18 -> 0
A19: Subtotal — Amman Support Personnel (Indirect / Admin) | K19: =SUM(K7:K18) -> 0
A21: B. Office, IT & Operational Costs (Indirect / Admin)
A22: B-01 | B22: S01 | C22: 2619 | D22: Amman | E22: Office Running Costs (rent share, utilities, stationery) | F22: Months | G22: 18 | H22: 1 | I22: 3000 | J22: 0.4 | K22: =G22*H22*I22*J22 -> 21600
A23: B-02 | B23: S01 | C23: 2609 | D23: Amman | E23: IT Equipment & Beneficiary Data Platform / Cyber Security | F23: Lump | G23: 1 | H23: 1 | I23: 30000 | J23: 0.4 | K23: =G23*H23*I23*J23 -> 12000
A24: B-03 | B24: S01 | C24: 2618 | D24: Amman | E24: Software Licenses & Subscriptions (accounting, MEAL, comms) | F24: Months | G24: 18 | H24: 1 | I24: 1000 | J24: 0.5 | K24: =G24*H24*I24*J24 -> 9000
A25: B-04 | B25: S01 | C25: 2625 | D25: Amman | E25: Communications (internet, telephone, postage) | F25: Staff | G25: 22 | H25: 18 | I25: 20 | J25: 1 | K25: =G25*H25*I25*J25 -> 7920
A26: B-05 | B26: S01 | C26: 2624 | D26: Amman | E26: Health Insurance (staff share) | F26: Lump | G26: 1 | H26: 1 | I26: 12000 | J26: 0.4 | K26: =G26*H26*I26*J26 -> 4800
A27: B-06 | B27: S01 | C27: 2627 | D27: Amman | E27: Social Security Contributions (employer share) | F27: Lump | G27: 1 | H27: 1 | I27: 30000 | J27: 0.35 | K27: =G27*H27*I27*J27 -> 10500
A28: B-07 | B28: S02 | C28: 2619 | D28: Gaza | E28: Center Rent (Gaza) | F28: Months | G28: 18 | H28: 1 | I28: 15000 | J28: 0.2 | K28: =G28*H28*I28*J28 -> 54000
A29: Subtotal — Office, IT & Operational Costs (Indirect / Admin) | K29: =SUM(K22:K28) -> 119820
A31: C. Statutory, Compliance, Risk & Contingency (Indirect / Admin)
A32: C-01 | B32: S01 | C32: 2622 | D32: Amman | E32: Audit, Legal & Compliance Fees | F32: Lump | G32: 1 | H32: 1 | I32: 18000 | J32: 1 | K32: =G32*H32*I32*J32 -> 18000
A33: C-02 | B33: S01 | C33: 2623 | D33: Amman | E33: Bank Charges & International Transfer Fees | F33: Lump | G33: 1 | H33: 1 | I33: 11000 | J33: 1 | K33: =G33*H33*I33*J33 -> 11000
A34: C-03 | B34: S01 | C34: 2623 | D34: Amman | E34: Recruitment & Onboarding | F34: Lump | G34: 1 | H34: 1 | I34: 5000 | J34: 0 | K34: =G34*H34*I34*J34 -> 0
A35: C-04 | B35: S01 | C35: 2615 | D35: Amman | E35: Staff Training & Professional Development | F35: Lump | G35: 1 | H35: 1 | I35: 7500 | J35: 1 | K35: =G35*H35*I35*J35 -> 7500
A36: C-05 | B36: S01 | C36: 2624 | D36: Amman | E36: Equipment Depreciation & Asset Insurance | F36: Lump | G36: 1 | H36: 1 | I36: 15000 | J36: 0 | K36: =G36*H36*I36*J36 -> 0
A37: C-06 | B37: S01 | C37: 2628 | D37: Amman & Field | E37: Contingency & Indirect Cost Reserve (to 15% ceiling) | F37: Lump | G37: 1 | H37: 1 | K37: =MAX(0,$K$43-(K19+K29+SUM(K32:K36))) -> 195895.93
A38: Subtotal — Statutory, Compliance, Risk & Contingency (Indirect / Admin) | K38: =SUM(K32:K37) -> 232395.93
A40: TOTAL ADMIN / INDIRECT COST | K40: =K19+K29+K38 -> 352215.93
A42: Exchange rate applied to Amman salaries (1 JOD = X USD): | K42: 1.41
A43: Indirect Cost Ceiling (% of Direct Cost): | J43: 0.15 | K43: =J43*'Direct Cost'!K48 -> 352215.93
A44: Indirect Cost as % of Direct Cost: | K44: =K40/'Direct Cost'!K48 -> 0.15

Sheet Budget Narrative
A1: RESTORING HOPE — Budget Narrative & Calculation Basis
A2: Code | B2: Budget Line | C2: Amount (USD) | D2: How it is Calculated | E2: Budget Narrative
A3: DIRECT COST
A4: A. Personnel — Gaza Field Team (100% Direct Cost)
A5: D-01 | B5: Project Manager | C5: ='Direct Cost'!K7 -> 0 | D5: 1 person × 18 months × $3,000/mo × 100% LoE | E5: Overall leadership, donor compliance, coordination of the mobile teams and reporting for the 300-case program. Full-time, dedicated to the project.
A6: D-02 | B6: Program Officer — Rehabilitation | C6: ='Direct Cost'!K8 -> 0 | D6: 1 × 18 months × $2,000/mo × 100% | E6: Supervises the Rehabilitation stream of the mobile teams and physiotherapy follow-up for all 300 patients.
A7: D-03 | B7: Program Officer — MHPSS | C7: ='Direct Cost'!K9 -> 0 | D7: 1 × 18 months × $2,000/mo × 100% | E7: Supervises the MHPSS stream; oversees individual counselling and group therapy protocols for all 300 patients.
A8: D-04 | B8: Mobile Team Member — Rehabilitation (x6) | C8: ='Direct Cost'!K10 -> 0 | D8: 6 staff × 18 months × $1,100/mo × 100% | E8: Six community-based Rehabilitation workers delivering physiotherapy and mobility follow-up across Gaza.
A9: D-05 | B9: Mobile Team Member — MHPSS (x6) | C9: ='Direct Cost'!K11 -> 0 | D9: 6 staff × 18 months × $1,100/mo × 100% | E9: Six community-based MHPSS workers delivering individual and group psychosocial support across Gaza.
A10: D-06 | B10: MEAL Officer | C10: ='Direct Cost'!K12 -> 0 | D10: 1 × 18 months × $1,100/mo × 100% | E10: Manages monitoring, patient and training data, the digital case-management dashboard, and logframe reporting (Annex 2).
A11: D-07 | B11: Photographer / Visibility Officer | C11: ='Direct Cost'!K13 -> 0 | D11: 1 × 18 months × $1,200/mo × 100% | E11: Documents program activities and patient journeys (with safeguarding protocols) and produces visibility material.
A12: D-08 | B12: Security Guard (x2) | C12: ='Direct Cost'!K14 -> 0 | D12: 2 guards × 18 months × $600/mo × 100% | E12: Provides site security for the P&O workshop and clinical facility (two guards).
A13: D-09 | B13: Cleaner (x2) | C13: ='Direct Cost'!K15 -> 0 | D13: 2 cleaners × 18 months × $600/mo × 100% | E13: Maintains hygiene and infection-control standards across the workshop and clinical zones (two cleaners).
A14: D-25 | B14: Logistic Officer | C14: ='Direct Cost'!K16 -> 0 | D14: 1 × 18 months × $2,000/mo × 100% | E14: Gaza-based logistics and procurement support for the project (moved from Admin to Direct).
A15: B. Specialist & Technical Personnel (Direct Cost)
A16: D-10 | B16: P&O Specialist Consultant (Academic & Clinical Oversight) | C16: ='Direct Cost'!K20 -> 15087 | D16: Lump sum = $15,087 (contract fee) | E16: Senior P&O consultant providing curriculum review, academic oversight, competency-framework validation and trainer supervision (Annex 3 TOR).
A17: D-13 | B17: Gaza University & University of Jordan Course Fees | C17: ='Direct Cost'!K21 -> 63619.2 | D17: 16 trainees × $3,976.20 course fee | E17: Joint academic delivery fee per trainee (16) covering Gaza University and University of Jordan P&O courses, leading to an accredited certificate.
A18: D-22 | B18: P&O Specialist (Amman-based, supporting Gaza) | C18: ='Direct Cost'!K22 -> 16200 | D18: 1 × 18 months × $3,000/mo × 30% LoE | E18: Amman-based P&O specialist providing technical support and supervision to the Gaza team; charged at 30%.
A19: D-23 | B19: Rehabilitation Specialist (Amman-based, supporting Gaza) | C19: ='Direct Cost'!K23 -> 16200 | D19: 1 × 18 months × $3,000/mo × 30% LoE | E19: Amman-based rehabilitation specialist supporting the Gaza mobile teams; charged at 30%.
A20: D-24 | B20: MHPSS Specialist (Amman-based, supporting Gaza) | C20: ='Direct Cost'!K24 -> 16200 | D20: 1 × 18 months × $3,000/mo × 30% LoE | E20: Amman-based MHPSS specialist supporting the Gaza mobile teams; charged at 30%.
A21: C. Capacity Building & Training Costs (Direct Cost)
A22: D-14a | B22: Trainee Incentives — Cohort 1 (8 trainees, 17 months) | C22: ='Direct Cost'!K28 -> 54400 | D22: 8 trainees × 17 months × $400/mo | E22: Monthly incentive for the first cohort of 8 P&O trainees for the 17 months enrolled, given the economic hardship in Gaza.
A23: D-14b | B23: Trainee Incentives — Cohort 2 (8 trainees, 12 months) | C23: ='Direct Cost'!K29 -> 38400 | D23: 8 trainees × 12 months × $400/mo | E23: Monthly incentive for the second cohort of 8 P&O trainees for the 12 months enrolled.
A24: D-15 | B24: Certified Expatriate Specialist Trainer and P&O (6 Specialist Trainers) | C24: ='Direct Cost'!K30 -> 168000 | D24: 8 trainers × 3 months × $7,000/mo | E24: Honoraria for specialist trainers delivering curriculum, hands-on training and patient-fitting supervision.
A25: D. Prosthetic Fitting & Integrated Patient Care — 300 Cases (Direct Cost)
A26: D-16 | B26: Prosthetic Components & Fabrication Materials (300 cases) | C26: ='Direct Cost'!K34 -> 500000 | D26: Lump sum = $500,000 (itemized in Annex 6) | E26: Full component and raw-material cost to fabricate and fit 300 lower-limb prosthetic devices; see Annex 6.
A27: D-17 | B27: Nutritional Support (300 HH) | C27: ='Direct Cost'!K35 -> 162000 | D27: 300 HH × 3 months × $180 each | E27: Nutritional assistance package per household to support recovery during fitting and rehabilitation. ESTIMATE.
A28: D-18 | B28: Patient Transport & Accompaniment (300 patients) | C28: ='Direct Cost'!K36 -> 45000 | D28: 12 months × $3,750/mo (transport pool) | E28: Transportation for fitting appointments and follow-up visits for all 300 patients. ESTIMATE.
A29: E. Workshop Equipment & Infrastructure (Direct Cost)
A30: D-19 | B30: P&O Workshop Machinery & Fabrication Equipment | C30: ='Direct Cost'!K40 -> 198000 | D30: Lump sum = $198,000 (Annex 1) | E30: Machinery and fabrication equipment across the 10 workshop zones; see Annex 1.
A31: D-20 | B31: Rehabilitation & MHPSS Zone Furnishing (Zone 10) | C31: ='Direct Cost'!K41 -> 25000 | D31: Lump sum = $25,000 | E31: Physiotherapy plinths, exercise equipment, soundproofed MHPSS room and nutritional assessment station. ESTIMATE.
A32: F. Visibility & Communications (Direct Cost)
A33: D-21 | B33: Communication & Visibility Materials | C33: ='Direct Cost'!K45 -> 30000 | D33: Lump sum = $30,000 | E33: Donor visibility and communication materials, signage and beneficiary story documentation; also covers the digital case-management / M&E platform. ESTIMATE.
A34: Subtotal — Direct Cost | C34: ='Direct Cost'!K48 -> 2348106.2
A36: ADMIN / INDIRECT COST
A37: A. Amman Support Personnel (Indirect / Admin — % LoE charged)
A38: A-01 | B38: Executive Director | C38: ='Admin Cost'!K7 -> 0 | D38: $5,640/mo × 18 months × 12% LoE | E38: Institutional leadership and accountability for the program; charged at 12% LoE.
A39: A-02 | B39: Program Director | C39: ='Admin Cost'!K8 -> 0 | D39: $4,935/mo × 18 × 18% | E39: Strategic oversight, donor compliance and inter-departmental coordination; 18% LoE.
A40: A-03 | B40: Grants & Compliance Officer | C40: ='Admin Cost'!K9 -> 0 | D40: $2,115/mo × 18 × 22% | E40: Grant compliance, narrative and financial reporting, donor communication; 22% LoE.
A41: A-04 | B41: Finance & Support Function Director | C41: ='Admin Cost'!K10 -> 0 | D41: $4,935/mo × 18 × 20% | E41: Financial management, budget monitoring and procurement oversight; 20% LoE.
...

Sheet Accounts & Activity
A1: Accounts Number | B1: Account | D1: Location | E1: Code
A2: Program Field Staff | B2: 2601 | D2: Amman | E2: 1
A3: Management Field Staff | B3: 2602 | D3: Gaza | E3: 2
A4: Head Office staff | B4: 2603 | D4: Sudan | E4: 3
A5: Support Field staff | B5: 2604 | D5: Syria | E5: 4
A6: Staff Transportation | B6: 2605 | D6: Lebanon | E6: 5
A7: Ben Transportation | B7: 2606 | D7: West Bank | E7: 6
A8: Car Rent | B8: 2607
A9: Fuel for generator or Car | B9: 2608
A10: IT Equipment | B10: 2609
A11: Project / Center Equipments | B11: 2610
A12: Prosthetics components | B12: 2611 | D12: Activity | E12: Code
A13: Media Equipments | B13: 2612 | D13: Support | E13: S
A14: Consultant | B14: 2613 | D14: Rehabilitation | E14: R
A15: Daily worker | B15: 2614 | D15: MHPSS | E15: M
A16: Training for staff | B16: 2615 | D16: Nutrition | E16: N
A17: International Travel | B17: 2616 | D17: P&O | E17: P
A18: Partnership | B18: 2617 | D18: Program Support / Management | E18: PM
A19: Subscription | B19: 2618
A20: Office Rent | B20: 2619
A21: Stationary | B21: 2620
A22: Workshops / Seminars / Team Building | B22: 2621
A23: Legal Fees | B23: 2622
A24: Bank Fees | B24: 2623
A25: Insurance | B25: 2624
A26: Telecommunication and Internet Cost | B26: 2625
A27: Nutrition and food | B27: 2626
A28: Social Security | B28: 2627
A29: Contingency | B29: 2628
